//
//  ResultType.swift
//  FoundationExtensions
//
//  Created by Luiz Barbosa on 30.11.18.
//  Copyright Â© 2018 Lautsprecher Teufel GmbH. All rights reserved.
//

import Foundation

public protocol ResultType: ResultConvertibleType {
    /// Initialize from a value
    ///
    /// - Parameter value: wrapped value when operation has succeeded
    init(value: Success)

    /// Initialize from an error
    ///
    /// - Parameter error: wrapped error when operation has failed
    init(error: Failure)

    /// Returns a new result, mapping any success value using the given
    /// transformation.
    ///
    /// Use this method when you need to transform the value of a `Result`
    /// instance when it represents a success. The following example transforms
    /// the integer success value of a result into a string:
    ///
    ///     func getNextInteger() -> Result<Int, Error> { /* ... */ }
    ///
    ///     let integerResult = getNextInteger()
    ///     // integerResult == .success(5)
    ///     let stringResult = integerResult.map({ String($0) })
    ///     // stringResult == .success("5")
    ///
    /// - Parameter transform: A closure that takes the success value of this
    ///   instance.
    /// - Returns: A `Result` instance with the result of evaluating `transform`
    ///   as the new success value if this instance represents a success.
    func map<NewSuccess>(_ transform: (Success) -> NewSuccess) -> Result<NewSuccess, Failure>

    /// Returns a new result, mapping any failure value using the given
    /// transformation.
    ///
    /// Use this method when you need to transform the value of a `Result`
    /// instance when it represents a failure. The following example transforms
    /// the error value of a result by wrapping it in a custom `Error` type:
    ///
    ///     struct DatedError: Error {
    ///         var error: Error
    ///         var date: Date
    ///
    ///         init(_ error: Error) {
    ///             self.error = error
    ///             self.date = Date()
    ///         }
    ///     }
    ///
    ///     let result: Result<Int, Error> = // ...
    ///     // result == .failure(<error value>)
    ///     let resultWithDatedError = result.mapError({ e in DatedError(e) })
    ///     // result == .failure(DatedError(error: <error value>, date: <date>))
    ///
    /// - Parameter transform: A closure that takes the failure value of the
    ///   instance.
    /// - Returns: A `Result` instance with the result of evaluating `transform`
    ///   as the new failure value if this instance represents a failure.
    func mapError<NewFailure>(_ transform: (Failure) -> NewFailure) -> Result<Success, NewFailure> where NewFailure: Error

    /// Returns a new result, mapping any success value using the given
    /// transformation and unwrapping the produced result.
    ///
    /// - Parameter transform: A closure that takes the success value of the
    ///   instance.
    /// - Returns: A `Result` instance with the result of evaluating `transform`
    ///   as the new failure value if this instance represents a failure.
    func flatMap<NewSuccess>(_ transform: (Success) -> Result<NewSuccess, Failure>) -> Result<NewSuccess, Failure>

    /// Returns a new result, mapping any failure value using the given
    /// transformation and unwrapping the produced result.
    ///
    /// - Parameter transform: A closure that takes the failure value of the
    ///   instance.
    /// - Returns: A `Result` instance, either from the closure or the previous
    ///   `.success`.
    func flatMapError<NewFailure>(_ transform: (Failure) -> Result<Success, NewFailure>) -> Result<Success, NewFailure> where NewFailure: Error

    /// Returns the success value as a throwing expression.
    ///
    /// Use this method to retrieve the value of this result if it represents a
    /// success, or to catch the value if it represents a failure.
    ///
    ///     let integerResult: Result<Int, Error> = .success(5)
    ///     do {
    ///         let value = try integerResult.get()
    ///         print("The value is \(value).")
    ///     } catch error {
    ///         print("Error retrieving the value: \(error)")
    ///     }
    ///     // Prints "The value is 5."
    ///
    /// - Returns: The success value, if the instance represents a success.
    /// - Throws: The failure value, if the instance represents a failure.
    func get() throws -> Success
}

extension ResultType where Success == Void {
    /// Convenience function that resolves to `Result<Void, Failure>.success(())` when `Success` type is `Void`
    /// Same approach introduced by Apple on Combine when `Output` is `Void`
    public static func success() -> Self {
        return .init(value: ())
    }
}
